{"status": "FAILURE", "result": {"exc_type": "NotADirectoryError", "exc_message": [20, "The directory name is invalid"], "exc_module": "builtins"}, "traceback": "Traceback (most recent call last):\n  File \"C:\\Users\\HP\\Desktop\\Enterprise_application\\Backend_Enterprise\\venv\\Lib\\site-packages\\celery\\app\\trace.py\", line 453, in trace_task\n    R = retval = fun(*args, **kwargs)\n                 ^^^^^^^^^^^^^^^^^^^^\n  File \"C:\\Users\\HP\\Desktop\\Enterprise_application\\Backend_Enterprise\\venv\\Lib\\site-packages\\celery\\app\\trace.py\", line 736, in __protected_call__\n    return self.run(*args, **kwargs)\n           ^^^^^^^^^^^^^^^^^^^^^^^^^\n  File \"C:\\Users\\HP\\Desktop\\Enterprise_application\\Backend_Enterprise\\delivery_system\\logfile\\tasks.py\", line 23, in process_evtx_folder\n    for filename in os.listdir(folder_path):\n                    ^^^^^^^^^^^^^^^^^^^^^^^\nNotADirectoryError: [WinError 267] The directory name is invalid: 'C:\\\\Users\\\\HP\\\\Desktop\\\\LoGs\\\\Setup.evtx'\n", "children": [], "date_done": "2025-09-25T08:06:48.774691+00:00", "task_id": "17df76ef-96b6-47c5-8c9a-1d5128d59296"}